# -*- coding: utf-8 -*-

from odoo import models, fields, api
from odoo.exceptions import ValidationError


class AgendarServicio(models.Model):
    _name = 'mz.agendar_servicio'
    _description = 'Agendar Servicio'
    _inherit = ['mail.thread', 'mail.activity.mixin']
    
    modulo_id = fields.Many2one(string='MÃ³dulo', comodel_name='pf.modulo', ondelete='restrict',
                                default=lambda self: self.env.ref('prefectura_base.modulo_2').id,tracking=True)
    beneficiario_id_domain = fields.Char(compute="_compute_beneficiario_id_domain", readonly=True, store=False, )
    beneficiario_id = fields.Many2one(string='Beneficiario', comodel_name='pf.beneficiario', ondelete='restrict', tracking=True, required=True)
    programa_id = fields.Many2one('pf.programas', string='Programa', required=True, default=lambda self: self.env.programa_id)

             
    @api.depends('modulo_id')
    def _compute_beneficiario_id_domain(self):
      for record in self:         
        beneficiario_ids = self.env['pf.beneficiario'].search([('modulo_ids', 'in', record.modulo_id.id)]).ids  
        record.beneficiario_id_domain = [('id', 'in', beneficiario_ids)]         
       
       
